<mujoco model="Quadruped_prestip">
  <option iterations="50" timestep="0.001" solver="PGS" gravity="0 0 -9.81" />

  <compiler angle="radian" meshdir="meshes" eulerseq="zyx" autolimits="true" />

  <default>
    <joint limited="true" damping="0.01" armature="0.01" frictionloss="0.01" />
    <geom condim="4" contype="1" conaffinity="15" friction="0.9 0.2 0.2" solref="0.001 2" />
    <motor ctrllimited="true" />
    <equality solref="0.001 2" />
    <default class="visualgeom">
      <geom material="visualgeom" condim="1" contype="0" conaffinity="0" />
    </default>
  </default>

  <asset>
    <mesh name="base_link" content_type="model/stl" file="base_link.STL" />
    <mesh name="leg_1_hip" content_type="model/stl" file="leg_1_hip.STL" />
    <mesh name="leg_1_knee" content_type="model/stl" file="leg_1_knee.STL" />
    <mesh name="leg_1_ankle" content_type="model/stl" file="leg_1_ankle.STL" />
    <mesh name="leg_2_hip" content_type="model/stl" file="leg_2_hip.STL" />
    <mesh name="leg_2_knee" content_type="model/stl" file="leg_2_knee.STL" />
    <mesh name="leg_2_ankle" content_type="model/stl" file="leg_2_ankle.STL" />
    <mesh name="leg_3_hip" content_type="model/stl" file="leg_3_hip.STL" />
    <mesh name="leg_3_knee" content_type="model/stl" file="leg_3_knee.STL" />
    <mesh name="leg_3_ankle" content_type="model/stl" file="leg_3_ankle.STL" />
    <mesh name="leg_4_hip" content_type="model/stl" file="leg_4_hip.STL" />
    <mesh name="leg_4_knee" content_type="model/stl" file="leg_4_knee.STL" />
    <mesh name="leg_4_ankle" content_type="model/stl" file="leg_4_ankle.STL" />
    <texture name="texplane" type="2d" builtin="checker" rgb1=".0 .0 .0" rgb2=".8 .8 .8" width="100" height="100" />
    <material name="matplane" reflectance="0." texture="texplane" texrepeat="1 1" texuniform="true" />
    <material name="visualgeom" rgba="0.5 0.9 0.2 1" />
  </asset>

  <worldbody>
    <light directional="true" diffuse="0.4 0.4 0.4" specular="0.1 0.1 0.1" pos="0 0 5.0" dir="0 0 -1" castshadow="false" />
    <light directional="true" diffuse="0.6 0.6 0.6" specular="0.2 0.2 0.2" pos="0 0 4" dir="0 0 -1" />
    <geom name="ground" type="plane" pos="0 0 0" size="100 100 0.001" quat="1 0 0 0" material="matplane" condim="3" conaffinity="15" />
    <camera name="fixed" pos="0 -3.0 0.6627932553930906" xyaxes="1 0 0 0 0 1" />
    <camera name="track" mode="trackcom" pos="0 -3.0 0.6627932553930906" xyaxes="1 0 0 0 0 1" />
    <body name="root" pos="0 0 0.16279325539309067" quat="1 0 0 0">
      <freejoint name="root" />
      <site name="imu" size="0.01" pos="0 0 0" />
      <geom type="mesh" rgba="0.894118 0.913725 0.929412 1" mesh="base_link" contype="1" conaffinity="0" density="0" group="1" class="visualgeom" />
      <geom type="mesh" rgba="0.894118 0.913725 0.929412 1" mesh="base_link" />
      <body name="leg_1_hip" pos="0.06197 -0.0825571 0.0385" quat="0 0.978224 -0.207552 0">
        <inertial pos="0.023894 0.0317926 0.0267813" quat="0.495152 0.000665368 0.000447992 0.868806" mass="0.0670778" diaginertia="2.55346e-05 2.31836e-05 1.06832e-05" />
        <joint name="leg1_hip_joint" pos="0 0 0" axis="0 0 1" range="-3 3" actuatorfrcrange="-10 10" />
        <geom type="mesh" rgba="0.894118 0.913725 0.929412 1" mesh="leg_1_hip" contype="1" conaffinity="0" density="0" group="1" class="visualgeom" />
        <geom type="mesh" rgba="0.894118 0.913725 0.929412 1" mesh="leg_1_hip" />
        <body name="leg_1_knee" pos="0.060665 0.04177 0.036307" quat="-2.59734e-06 0.707105 -0.707108 2.59735e-06">
          <inertial pos="-0.0387166 0.0235365 -0.034535" quat="0.634858 0.693632 0.228094 -0.252591" mass="0.0696915" diaginertia="2.5879e-05 2.56996e-05 1.97167e-05" />
          <joint name="leg_1_knee_joint" pos="0 0 0" axis="0 -1 0" range="-3 3" actuatorfrcrange="-10 10" />
          <geom type="mesh" rgba="0.298039 0.298039 0.298039 1" mesh="leg_1_knee" contype="1" conaffinity="0" density="0" group="1" class="visualgeom" />
          <geom type="mesh" rgba="0.298039 0.298039 0.298039 1" mesh="leg_1_knee" />
          <body name="leg_1_ankle" pos="-0.0422926 0.0005 -0.049058" quat="0.491206 0 -0.871044 0">
            <inertial pos="-3.98306e-12 0.0280775 0.0172277" quat="0.707107 0.707107 0 0" mass="0.0169824" diaginertia="1.11378e-05 9.36668e-06 3.3936e-06" />
            <joint name="leg_1_ankle_joint" pos="0 0 0" axis="0 -1 0" range="-3 3" actuatorfrcrange="-10 10" />
            <geom type="mesh" rgba="0.298039 0.298039 0.298039 1" mesh="leg_1_ankle" contype="1" conaffinity="0" density="0" group="1" class="visualgeom" />
            <geom type="mesh" rgba="0.298039 0.298039 0.298039 1" mesh="leg_1_ankle" />
          </body>
        </body>
      </body>
      <body name="leg_2_hip" pos="0.06177 0.0055571 0.0385" quat="-3.53769e-06 0.963106 0.269121 -9.88536e-07">
        <inertial pos="0.023894 -0.0318845 0.0267812" quat="0.868806 0.000443767 0.000665763 0.495152" mass="0.0670778" diaginertia="2.55346e-05 2.31836e-05 1.06832e-05" />
        <joint name="leg_2_hip_joint" pos="0 0 0" axis="0 0 -1" range="-3 3" actuatorfrcrange="-10 10" />
        <geom type="mesh" rgba="0.894118 0.913725 0.929412 1" mesh="leg_2_hip" contype="1" conaffinity="0" density="0" group="1" class="visualgeom" />
        <geom type="mesh" rgba="0.894118 0.913725 0.929412 1" mesh="leg_2_hip" />
        <body name="leg_2_knee" pos="0.060665 -0.04197 0.0363071" quat="0.707107 0 0 0.707107">
          <inertial pos="0.011055 0.0235365 0.0506895" quat="0.726352 0.663246 0.131683 -0.123196" mass="0.0696915" diaginertia="2.5879e-05 2.56996e-05 1.97167e-05" />
          <joint name="leg_2_knee_joint" pos="0 0 0" axis="0 -1 0" range="-3 3" actuatorfrcrange="-10 10" />
          <geom type="mesh" rgba="0.894118 0.913725 0.929412 1" mesh="leg_2_knee" contype="1" conaffinity="0" density="0" group="1" class="visualgeom" />
          <geom type="mesh" rgba="0.894118 0.913725 0.929412 1" mesh="leg_2_knee" />
          <body name="leg_2_ankle" pos="0.0219469 0.0005 0.06094" quat="0.984145 0 0.177367 0">
            <inertial pos="0 0.0280775 0.0172277" quat="0.707107 0.707107 0 0" mass="0.0169824" diaginertia="1.11378e-05 9.36668e-06 3.3936e-06" />
            <joint name="leg_2_ankle_joint" pos="0 0 0" axis="0 -1 0" range="-3 3" actuatorfrcrange="-10 10" />
            <geom type="mesh" rgba="0.894118 0.913725 0.929412 1" mesh="leg_2_ankle" contype="1" conaffinity="0" density="0" group="1" class="visualgeom" />
            <geom type="mesh" rgba="0.894118 0.913725 0.929412 1" mesh="leg_2_ankle" />
          </body>
        </body>
      </body>
      <body name="leg_3_hip" pos="-0.04277 0.0055571 0.0395" quat="-6.31625e-08 -0.0171955 -0.999852 -3.67266e-06">
        <inertial pos="0.0241829 0.032177 0.0275026" quat="0.495152 0.000664423 0.000447229 0.868806" mass="0.0662765" diaginertia="2.55132e-05 2.31621e-05 1.06429e-05" />
        <joint name="leg_3_hip_joint" pos="0 0 0" axis="0 0 1" range="-3 3" actuatorfrcrange="-10 10" />
        <geom type="mesh" rgba="0.894118 0.913725 0.929412 1" mesh="leg_3_hip" contype="1" conaffinity="0" density="0" group="1" class="visualgeom" />
        <geom type="mesh" rgba="0.894118 0.913725 0.929412 1" mesh="leg_3_hip" />
        <body name="leg_3_knee" pos="0.060665 0.04177 0.0373071" quat="0.707107 0 0 0.707107">
          <inertial pos="0.0225358 0.0235365 0.0467309" quat="0.729604 0.667178 0.112278 -0.0997296" mass="0.0696915" diaginertia="2.5879e-05 2.56996e-05 1.97167e-05" />
          <joint name="leg_3_knee_joint" pos="0 0 0" axis="0 1 0" range="-3 3" actuatorfrcrange="-10 10" />
          <geom type="mesh" rgba="0.298039 0.298039 0.298039 1" mesh="leg_3_knee" contype="1" conaffinity="0" density="0" group="1" class="visualgeom" />
          <geom type="mesh" rgba="0.298039 0.298039 0.298039 1" mesh="leg_3_knee" />
          <body name="leg_3_ankle" pos="0.0202762 0.0005 0.0615161" quat="0 0.990581 0 0.136931">
            <inertial pos="0 -0.0280775 -0.0172277" quat="0.707107 0.707107 0 0" mass="0.0169824" diaginertia="1.11378e-05 9.36668e-06 3.3936e-06" />
            <joint name="leg_3_ankle" pos="0 0 0" axis="0 -1 0" range="-3 3" actuatorfrcrange="-10 10" />
            <geom type="mesh" rgba="0.894118 0.913725 0.929412 1" mesh="leg_3_ankle" contype="1" conaffinity="0" density="0" group="1" class="visualgeom" />
            <geom type="mesh" rgba="0.894118 0.913725 0.929412 1" mesh="leg_3_ankle" />
          </body>
        </body>
      </body>
      <body name="leg_4_hip" pos="-0.04277 -0.0825571 0.0385" quat="0 -0.35339 -0.935476 0">
        <inertial pos="0.0241829 -0.032177 0.0265024" quat="0.868806 0.000443092 0.000664861 0.495152" mass="0.0662765" diaginertia="2.55132e-05 2.31621e-05 1.06429e-05" />
        <joint name="leg_4_hip_joint" pos="0 0 0" axis="0 0 -1" range="-3 3" actuatorfrcrange="-10 10" />
        <geom type="mesh" rgba="0.298039 0.298039 0.298039 1" mesh="leg_4_hip" contype="1" conaffinity="0" density="0" group="1" class="visualgeom" />
        <geom type="mesh" rgba="0.298039 0.298039 0.298039 1" mesh="leg_4_hip" />
        <body name="leg_4_knee" pos="0.060665 -0.04177 0.0363071" quat="0.707107 0 0 -0.707107">
          <inertial pos="0.0094234 -0.0235365 0.051018" quat="0.674514 0.738054 0.0101414 -0.0142785" mass="0.0696915" diaginertia="2.5879e-05 2.56996e-05 1.97167e-05" />
          <joint name="leg_4_knee_joint" pos="0 0 0" axis="0 -1 0" range="-3 3" actuatorfrcrange="-10 10" />
          <geom type="mesh" rgba="0.894118 0.913725 0.929412 1" mesh="leg_4_knee" contype="1" conaffinity="0" density="0" group="1" class="visualgeom" />
          <geom type="mesh" rgba="0.894118 0.913725 0.929412 1" mesh="leg_4_knee" />
          <body name="leg_4_ankle" pos="0.00334718 -0.0005 0.064685" quat="0.256985 0 -0.966416 0">
            <inertial pos="0 -0.0280775 -0.0172277" quat="0.707107 0.707107 0 0" mass="0.0169824" diaginertia="1.11378e-05 9.36668e-06 3.3936e-06" />
            <joint name="leg_4_ankle_joint" pos="0 0 0" axis="0 -1 0" range="-3 3" actuatorfrcrange="-10 10" />
            <geom type="mesh" rgba="0.894118 0.913725 0.929412 1" mesh="leg_4_ankle" contype="1" conaffinity="0" density="0" group="1" class="visualgeom" />
            <geom type="mesh" rgba="0.894118 0.913725 0.929412 1" mesh="leg_4_ankle" />
          </body>
        </body>
      </body>
    </body>
  </worldbody>

  <actuator>
    <motor name="leg1_hip_joint" joint="leg1_hip_joint" ctrllimited="true" ctrlrange="-10 10" gear="1" />
    <motor name="leg_1_knee_joint" joint="leg_1_knee_joint" ctrllimited="true" ctrlrange="-10 10" gear="1" />
    <motor name="leg_1_ankle_joint" joint="leg_1_ankle_joint" ctrllimited="true" ctrlrange="-10 10" gear="1" />
    <motor name="leg_2_hip_joint" joint="leg_2_hip_joint" ctrllimited="true" ctrlrange="-10 10" gear="1" />
    <motor name="leg_2_knee_joint" joint="leg_2_knee_joint" ctrllimited="true" ctrlrange="-10 10" gear="1" />
    <motor name="leg_2_ankle_joint" joint="leg_2_ankle_joint" ctrllimited="true" ctrlrange="-10 10" gear="1" />
    <motor name="leg_3_hip_joint" joint="leg_3_hip_joint" ctrllimited="true" ctrlrange="-10 10" gear="1" />
    <motor name="leg_3_knee_joint" joint="leg_3_knee_joint" ctrllimited="true" ctrlrange="-10 10" gear="1" />
    <motor name="leg_3_ankle" joint="leg_3_ankle" ctrllimited="true" ctrlrange="-10 10" gear="1" />
    <motor name="leg_4_hip_joint" joint="leg_4_hip_joint" ctrllimited="true" ctrlrange="-10 10" gear="1" />
    <motor name="leg_4_knee_joint" joint="leg_4_knee_joint" ctrllimited="true" ctrlrange="-10 10" gear="1" />
    <motor name="leg_4_ankle_joint" joint="leg_4_ankle_joint" ctrllimited="true" ctrlrange="-10 10" gear="1" />
  </actuator>

  <sensor>
    <actuatorpos name="leg1_hip_joint_p" actuator="leg1_hip_joint" />
    <actuatorvel name="leg1_hip_joint_v" actuator="leg1_hip_joint" />
    <actuatorfrc name="leg1_hip_joint_f" actuator="leg1_hip_joint" noise="0.001" />
    <actuatorpos name="leg_1_knee_joint_p" actuator="leg_1_knee_joint" />
    <actuatorvel name="leg_1_knee_joint_v" actuator="leg_1_knee_joint" />
    <actuatorfrc name="leg_1_knee_joint_f" actuator="leg_1_knee_joint" noise="0.001" />
    <actuatorpos name="leg_1_ankle_joint_p" actuator="leg_1_ankle_joint" />
    <actuatorvel name="leg_1_ankle_joint_v" actuator="leg_1_ankle_joint" />
    <actuatorfrc name="leg_1_ankle_joint_f" actuator="leg_1_ankle_joint" noise="0.001" />
    <actuatorpos name="leg_2_hip_joint_p" actuator="leg_2_hip_joint" />
    <actuatorvel name="leg_2_hip_joint_v" actuator="leg_2_hip_joint" />
    <actuatorfrc name="leg_2_hip_joint_f" actuator="leg_2_hip_joint" noise="0.001" />
    <actuatorpos name="leg_2_knee_joint_p" actuator="leg_2_knee_joint" />
    <actuatorvel name="leg_2_knee_joint_v" actuator="leg_2_knee_joint" />
    <actuatorfrc name="leg_2_knee_joint_f" actuator="leg_2_knee_joint" noise="0.001" />
    <actuatorpos name="leg_2_ankle_joint_p" actuator="leg_2_ankle_joint" />
    <actuatorvel name="leg_2_ankle_joint_v" actuator="leg_2_ankle_joint" />
    <actuatorfrc name="leg_2_ankle_joint_f" actuator="leg_2_ankle_joint" noise="0.001" />
    <actuatorpos name="leg_3_hip_joint_p" actuator="leg_3_hip_joint" />
    <actuatorvel name="leg_3_hip_joint_v" actuator="leg_3_hip_joint" />
    <actuatorfrc name="leg_3_hip_joint_f" actuator="leg_3_hip_joint" noise="0.001" />
    <actuatorpos name="leg_3_knee_joint_p" actuator="leg_3_knee_joint" />
    <actuatorvel name="leg_3_knee_joint_v" actuator="leg_3_knee_joint" />
    <actuatorfrc name="leg_3_knee_joint_f" actuator="leg_3_knee_joint" noise="0.001" />
    <actuatorpos name="leg_3_ankle_p" actuator="leg_3_ankle" />
    <actuatorvel name="leg_3_ankle_v" actuator="leg_3_ankle" />
    <actuatorfrc name="leg_3_ankle_f" actuator="leg_3_ankle" noise="0.001" />
    <actuatorpos name="leg_4_hip_joint_p" actuator="leg_4_hip_joint" />
    <actuatorvel name="leg_4_hip_joint_v" actuator="leg_4_hip_joint" />
    <actuatorfrc name="leg_4_hip_joint_f" actuator="leg_4_hip_joint" noise="0.001" />
    <actuatorpos name="leg_4_knee_joint_p" actuator="leg_4_knee_joint" />
    <actuatorvel name="leg_4_knee_joint_v" actuator="leg_4_knee_joint" />
    <actuatorfrc name="leg_4_knee_joint_f" actuator="leg_4_knee_joint" noise="0.001" />
    <actuatorpos name="leg_4_ankle_joint_p" actuator="leg_4_ankle_joint" />
    <actuatorvel name="leg_4_ankle_joint_v" actuator="leg_4_ankle_joint" />
    <actuatorfrc name="leg_4_ankle_joint_f" actuator="leg_4_ankle_joint" noise="0.001" />
    <framequat name="orientation" objtype="site" noise="0.001" objname="imu" />
    <gyro name="angular-velocity" site="imu" noise="0.005" cutoff="34.9" />
  </sensor>
</mujoco>